{
 "cells": [
  {
   "cell_type": "code",
   "execution_count": 1,
   "id": "1d7f86a5-96de-43ac-a3b0-f342e5d8b26b",
   "metadata": {},
   "outputs": [
    {
     "name": "stderr",
     "output_type": "stream",
     "text": [
      "\n",
      "A module that was compiled using NumPy 1.x cannot be run in\n",
      "NumPy 2.2.6 as it may crash. To support both 1.x and 2.x\n",
      "versions of NumPy, modules must be compiled with NumPy 2.0.\n",
      "Some module may need to rebuild instead e.g. with 'pybind11>=2.12'.\n",
      "\n",
      "If you are a user of the module, the easiest solution will be to\n",
      "downgrade to 'numpy<2' or try to upgrade the affected module.\n",
      "We expect that some modules will need time to support NumPy 2.\n",
      "\n",
      "Traceback (most recent call last):  File \"/opt/conda/lib/python3.10/runpy.py\", line 196, in _run_module_as_main\n",
      "    return _run_code(code, main_globals, None,\n",
      "  File \"/opt/conda/lib/python3.10/runpy.py\", line 86, in _run_code\n",
      "    exec(code, run_globals)\n",
      "  File \"/opt/conda/lib/python3.10/site-packages/ipykernel_launcher.py\", line 17, in <module>\n",
      "    app.launch_new_instance()\n",
      "  File \"/opt/conda/lib/python3.10/site-packages/traitlets/config/application.py\", line 1041, in launch_instance\n",
      "    app.start()\n",
      "  File \"/opt/conda/lib/python3.10/site-packages/ipykernel/kernelapp.py\", line 711, in start\n",
      "    self.io_loop.start()\n",
      "  File \"/opt/conda/lib/python3.10/site-packages/tornado/platform/asyncio.py\", line 215, in start\n",
      "    self.asyncio_loop.run_forever()\n",
      "  File \"/opt/conda/lib/python3.10/asyncio/base_events.py\", line 603, in run_forever\n",
      "    self._run_once()\n",
      "  File \"/opt/conda/lib/python3.10/asyncio/base_events.py\", line 1899, in _run_once\n",
      "    handle._run()\n",
      "  File \"/opt/conda/lib/python3.10/asyncio/events.py\", line 80, in _run\n",
      "    self._context.run(self._callback, *self._args)\n",
      "  File \"/opt/conda/lib/python3.10/site-packages/ipykernel/kernelbase.py\", line 510, in dispatch_queue\n",
      "    await self.process_one()\n",
      "  File \"/opt/conda/lib/python3.10/site-packages/ipykernel/kernelbase.py\", line 499, in process_one\n",
      "    await dispatch(*args)\n",
      "  File \"/opt/conda/lib/python3.10/site-packages/ipykernel/kernelbase.py\", line 406, in dispatch_shell\n",
      "    await result\n",
      "  File \"/opt/conda/lib/python3.10/site-packages/ipykernel/kernelbase.py\", line 729, in execute_request\n",
      "    reply_content = await reply_content\n",
      "  File \"/opt/conda/lib/python3.10/site-packages/ipykernel/ipkernel.py\", line 411, in do_execute\n",
      "    res = shell.run_cell(\n",
      "  File \"/opt/conda/lib/python3.10/site-packages/ipykernel/zmqshell.py\", line 530, in run_cell\n",
      "    return super().run_cell(*args, **kwargs)\n",
      "  File \"/opt/conda/lib/python3.10/site-packages/IPython/core/interactiveshell.py\", line 2945, in run_cell\n",
      "    result = self._run_cell(\n",
      "  File \"/opt/conda/lib/python3.10/site-packages/IPython/core/interactiveshell.py\", line 3000, in _run_cell\n",
      "    return runner(coro)\n",
      "  File \"/opt/conda/lib/python3.10/site-packages/IPython/core/async_helpers.py\", line 129, in _pseudo_sync_runner\n",
      "    coro.send(None)\n",
      "  File \"/opt/conda/lib/python3.10/site-packages/IPython/core/interactiveshell.py\", line 3203, in run_cell_async\n",
      "    has_raised = await self.run_ast_nodes(code_ast.body, cell_name,\n",
      "  File \"/opt/conda/lib/python3.10/site-packages/IPython/core/interactiveshell.py\", line 3382, in run_ast_nodes\n",
      "    if await self.run_code(code, result, async_=asy):\n",
      "  File \"/opt/conda/lib/python3.10/site-packages/IPython/core/interactiveshell.py\", line 3442, in run_code\n",
      "    exec(code_obj, self.user_global_ns, self.user_ns)\n",
      "  File \"/tmp/ipykernel_14610/3049354109.py\", line 7, in <module>\n",
      "    from spark_session import spark\n",
      "  File \"/home/user/work/spark_session.py\", line 8, in <module>\n",
      "    import pandas as pd\n",
      "  File \"/opt/conda/lib/python3.10/site-packages/pandas/__init__.py\", line 26, in <module>\n",
      "    from pandas.compat import (\n",
      "  File \"/opt/conda/lib/python3.10/site-packages/pandas/compat/__init__.py\", line 27, in <module>\n",
      "    from pandas.compat.pyarrow import (\n",
      "  File \"/opt/conda/lib/python3.10/site-packages/pandas/compat/pyarrow.py\", line 8, in <module>\n",
      "    import pyarrow as pa\n",
      "  File \"/opt/conda/lib/python3.10/site-packages/pyarrow/__init__.py\", line 65, in <module>\n",
      "    import pyarrow.lib as _lib\n"
     ]
    },
    {
     "ename": "AttributeError",
     "evalue": "_ARRAY_API not found",
     "output_type": "error",
     "traceback": [
      "\u001b[0;31m---------------------------------------------------------------------------\u001b[0m",
      "\u001b[0;31mAttributeError\u001b[0m                            Traceback (most recent call last)",
      "\u001b[0;31mAttributeError\u001b[0m: _ARRAY_API not found"
     ]
    },
    {
     "name": "stderr",
     "output_type": "stream",
     "text": [
      "\n",
      "A module that was compiled using NumPy 1.x cannot be run in\n",
      "NumPy 2.2.6 as it may crash. To support both 1.x and 2.x\n",
      "versions of NumPy, modules must be compiled with NumPy 2.0.\n",
      "Some module may need to rebuild instead e.g. with 'pybind11>=2.12'.\n",
      "\n",
      "If you are a user of the module, the easiest solution will be to\n",
      "downgrade to 'numpy<2' or try to upgrade the affected module.\n",
      "We expect that some modules will need time to support NumPy 2.\n",
      "\n",
      "Traceback (most recent call last):  File \"/opt/conda/lib/python3.10/runpy.py\", line 196, in _run_module_as_main\n",
      "    return _run_code(code, main_globals, None,\n",
      "  File \"/opt/conda/lib/python3.10/runpy.py\", line 86, in _run_code\n",
      "    exec(code, run_globals)\n",
      "  File \"/opt/conda/lib/python3.10/site-packages/ipykernel_launcher.py\", line 17, in <module>\n",
      "    app.launch_new_instance()\n",
      "  File \"/opt/conda/lib/python3.10/site-packages/traitlets/config/application.py\", line 1041, in launch_instance\n",
      "    app.start()\n",
      "  File \"/opt/conda/lib/python3.10/site-packages/ipykernel/kernelapp.py\", line 711, in start\n",
      "    self.io_loop.start()\n",
      "  File \"/opt/conda/lib/python3.10/site-packages/tornado/platform/asyncio.py\", line 215, in start\n",
      "    self.asyncio_loop.run_forever()\n",
      "  File \"/opt/conda/lib/python3.10/asyncio/base_events.py\", line 603, in run_forever\n",
      "    self._run_once()\n",
      "  File \"/opt/conda/lib/python3.10/asyncio/base_events.py\", line 1899, in _run_once\n",
      "    handle._run()\n",
      "  File \"/opt/conda/lib/python3.10/asyncio/events.py\", line 80, in _run\n",
      "    self._context.run(self._callback, *self._args)\n",
      "  File \"/opt/conda/lib/python3.10/site-packages/ipykernel/kernelbase.py\", line 510, in dispatch_queue\n",
      "    await self.process_one()\n",
      "  File \"/opt/conda/lib/python3.10/site-packages/ipykernel/kernelbase.py\", line 499, in process_one\n",
      "    await dispatch(*args)\n",
      "  File \"/opt/conda/lib/python3.10/site-packages/ipykernel/kernelbase.py\", line 406, in dispatch_shell\n",
      "    await result\n",
      "  File \"/opt/conda/lib/python3.10/site-packages/ipykernel/kernelbase.py\", line 729, in execute_request\n",
      "    reply_content = await reply_content\n",
      "  File \"/opt/conda/lib/python3.10/site-packages/ipykernel/ipkernel.py\", line 411, in do_execute\n",
      "    res = shell.run_cell(\n",
      "  File \"/opt/conda/lib/python3.10/site-packages/ipykernel/zmqshell.py\", line 530, in run_cell\n",
      "    return super().run_cell(*args, **kwargs)\n",
      "  File \"/opt/conda/lib/python3.10/site-packages/IPython/core/interactiveshell.py\", line 2945, in run_cell\n",
      "    result = self._run_cell(\n",
      "  File \"/opt/conda/lib/python3.10/site-packages/IPython/core/interactiveshell.py\", line 3000, in _run_cell\n",
      "    return runner(coro)\n",
      "  File \"/opt/conda/lib/python3.10/site-packages/IPython/core/async_helpers.py\", line 129, in _pseudo_sync_runner\n",
      "    coro.send(None)\n",
      "  File \"/opt/conda/lib/python3.10/site-packages/IPython/core/interactiveshell.py\", line 3203, in run_cell_async\n",
      "    has_raised = await self.run_ast_nodes(code_ast.body, cell_name,\n",
      "  File \"/opt/conda/lib/python3.10/site-packages/IPython/core/interactiveshell.py\", line 3382, in run_ast_nodes\n",
      "    if await self.run_code(code, result, async_=asy):\n",
      "  File \"/opt/conda/lib/python3.10/site-packages/IPython/core/interactiveshell.py\", line 3442, in run_code\n",
      "    exec(code_obj, self.user_global_ns, self.user_ns)\n",
      "  File \"/tmp/ipykernel_14610/3049354109.py\", line 7, in <module>\n",
      "    from spark_session import spark\n",
      "  File \"/home/user/work/spark_session.py\", line 8, in <module>\n",
      "    import pandas as pd\n",
      "  File \"/opt/conda/lib/python3.10/site-packages/pandas/__init__.py\", line 49, in <module>\n",
      "    from pandas.core.api import (\n",
      "  File \"/opt/conda/lib/python3.10/site-packages/pandas/core/api.py\", line 9, in <module>\n",
      "    from pandas.core.dtypes.dtypes import (\n",
      "  File \"/opt/conda/lib/python3.10/site-packages/pandas/core/dtypes/dtypes.py\", line 24, in <module>\n",
      "    from pandas._libs import (\n",
      "  File \"/opt/conda/lib/python3.10/site-packages/pyarrow/__init__.py\", line 65, in <module>\n",
      "    import pyarrow.lib as _lib\n"
     ]
    },
    {
     "ename": "AttributeError",
     "evalue": "_ARRAY_API not found",
     "output_type": "error",
     "traceback": [
      "\u001b[0;31m---------------------------------------------------------------------------\u001b[0m",
      "\u001b[0;31mAttributeError\u001b[0m                            Traceback (most recent call last)",
      "\u001b[0;31mAttributeError\u001b[0m: _ARRAY_API not found"
     ]
    },
    {
     "name": "stderr",
     "output_type": "stream",
     "text": [
      "\n",
      "A module that was compiled using NumPy 1.x cannot be run in\n",
      "NumPy 2.2.6 as it may crash. To support both 1.x and 2.x\n",
      "versions of NumPy, modules must be compiled with NumPy 2.0.\n",
      "Some module may need to rebuild instead e.g. with 'pybind11>=2.12'.\n",
      "\n",
      "If you are a user of the module, the easiest solution will be to\n",
      "downgrade to 'numpy<2' or try to upgrade the affected module.\n",
      "We expect that some modules will need time to support NumPy 2.\n",
      "\n",
      "Traceback (most recent call last):  File \"/opt/conda/lib/python3.10/runpy.py\", line 196, in _run_module_as_main\n",
      "    return _run_code(code, main_globals, None,\n",
      "  File \"/opt/conda/lib/python3.10/runpy.py\", line 86, in _run_code\n",
      "    exec(code, run_globals)\n",
      "  File \"/opt/conda/lib/python3.10/site-packages/ipykernel_launcher.py\", line 17, in <module>\n",
      "    app.launch_new_instance()\n",
      "  File \"/opt/conda/lib/python3.10/site-packages/traitlets/config/application.py\", line 1041, in launch_instance\n",
      "    app.start()\n",
      "  File \"/opt/conda/lib/python3.10/site-packages/ipykernel/kernelapp.py\", line 711, in start\n",
      "    self.io_loop.start()\n",
      "  File \"/opt/conda/lib/python3.10/site-packages/tornado/platform/asyncio.py\", line 215, in start\n",
      "    self.asyncio_loop.run_forever()\n",
      "  File \"/opt/conda/lib/python3.10/asyncio/base_events.py\", line 603, in run_forever\n",
      "    self._run_once()\n",
      "  File \"/opt/conda/lib/python3.10/asyncio/base_events.py\", line 1899, in _run_once\n",
      "    handle._run()\n",
      "  File \"/opt/conda/lib/python3.10/asyncio/events.py\", line 80, in _run\n",
      "    self._context.run(self._callback, *self._args)\n",
      "  File \"/opt/conda/lib/python3.10/site-packages/ipykernel/kernelbase.py\", line 510, in dispatch_queue\n",
      "    await self.process_one()\n",
      "  File \"/opt/conda/lib/python3.10/site-packages/ipykernel/kernelbase.py\", line 499, in process_one\n",
      "    await dispatch(*args)\n",
      "  File \"/opt/conda/lib/python3.10/site-packages/ipykernel/kernelbase.py\", line 406, in dispatch_shell\n",
      "    await result\n",
      "  File \"/opt/conda/lib/python3.10/site-packages/ipykernel/kernelbase.py\", line 729, in execute_request\n",
      "    reply_content = await reply_content\n",
      "  File \"/opt/conda/lib/python3.10/site-packages/ipykernel/ipkernel.py\", line 411, in do_execute\n",
      "    res = shell.run_cell(\n",
      "  File \"/opt/conda/lib/python3.10/site-packages/ipykernel/zmqshell.py\", line 530, in run_cell\n",
      "    return super().run_cell(*args, **kwargs)\n",
      "  File \"/opt/conda/lib/python3.10/site-packages/IPython/core/interactiveshell.py\", line 2945, in run_cell\n",
      "    result = self._run_cell(\n",
      "  File \"/opt/conda/lib/python3.10/site-packages/IPython/core/interactiveshell.py\", line 3000, in _run_cell\n",
      "    return runner(coro)\n",
      "  File \"/opt/conda/lib/python3.10/site-packages/IPython/core/async_helpers.py\", line 129, in _pseudo_sync_runner\n",
      "    coro.send(None)\n",
      "  File \"/opt/conda/lib/python3.10/site-packages/IPython/core/interactiveshell.py\", line 3203, in run_cell_async\n",
      "    has_raised = await self.run_ast_nodes(code_ast.body, cell_name,\n",
      "  File \"/opt/conda/lib/python3.10/site-packages/IPython/core/interactiveshell.py\", line 3382, in run_ast_nodes\n",
      "    if await self.run_code(code, result, async_=asy):\n",
      "  File \"/opt/conda/lib/python3.10/site-packages/IPython/core/interactiveshell.py\", line 3442, in run_code\n",
      "    exec(code_obj, self.user_global_ns, self.user_ns)\n",
      "  File \"/tmp/ipykernel_14610/3049354109.py\", line 7, in <module>\n",
      "    from spark_session import spark\n",
      "  File \"/home/user/work/spark_session.py\", line 8, in <module>\n",
      "    import pandas as pd\n",
      "  File \"/opt/conda/lib/python3.10/site-packages/pandas/__init__.py\", line 49, in <module>\n",
      "    from pandas.core.api import (\n",
      "  File \"/opt/conda/lib/python3.10/site-packages/pandas/core/api.py\", line 28, in <module>\n",
      "    from pandas.core.arrays import Categorical\n",
      "  File \"/opt/conda/lib/python3.10/site-packages/pandas/core/arrays/__init__.py\", line 1, in <module>\n",
      "    from pandas.core.arrays.arrow import ArrowExtensionArray\n",
      "  File \"/opt/conda/lib/python3.10/site-packages/pandas/core/arrays/arrow/__init__.py\", line 5, in <module>\n",
      "    from pandas.core.arrays.arrow.array import ArrowExtensionArray\n",
      "  File \"/opt/conda/lib/python3.10/site-packages/pandas/core/arrays/arrow/array.py\", line 52, in <module>\n",
      "    from pandas.core import (\n",
      "  File \"/opt/conda/lib/python3.10/site-packages/pandas/core/ops/__init__.py\", line 8, in <module>\n",
      "    from pandas.core.ops.array_ops import (\n",
      "  File \"/opt/conda/lib/python3.10/site-packages/pandas/core/ops/array_ops.py\", line 56, in <module>\n",
      "    from pandas.core.computation import expressions\n",
      "  File \"/opt/conda/lib/python3.10/site-packages/pandas/core/computation/expressions.py\", line 21, in <module>\n",
      "    from pandas.core.computation.check import NUMEXPR_INSTALLED\n",
      "  File \"/opt/conda/lib/python3.10/site-packages/pandas/core/computation/check.py\", line 5, in <module>\n",
      "    ne = import_optional_dependency(\"numexpr\", errors=\"warn\")\n",
      "  File \"/opt/conda/lib/python3.10/site-packages/pandas/compat/_optional.py\", line 135, in import_optional_dependency\n",
      "    module = importlib.import_module(name)\n",
      "  File \"/opt/conda/lib/python3.10/importlib/__init__.py\", line 126, in import_module\n",
      "    return _bootstrap._gcd_import(name[level:], package, level)\n",
      "  File \"/opt/conda/lib/python3.10/site-packages/numexpr/__init__.py\", line 24, in <module>\n",
      "    from numexpr.interpreter import MAX_THREADS, use_vml, __BLOCK_SIZE1__\n"
     ]
    },
    {
     "ename": "AttributeError",
     "evalue": "_ARRAY_API not found",
     "output_type": "error",
     "traceback": [
      "\u001b[0;31m---------------------------------------------------------------------------\u001b[0m",
      "\u001b[0;31mAttributeError\u001b[0m                            Traceback (most recent call last)",
      "\u001b[0;31mAttributeError\u001b[0m: _ARRAY_API not found"
     ]
    },
    {
     "name": "stderr",
     "output_type": "stream",
     "text": [
      "\n",
      "A module that was compiled using NumPy 1.x cannot be run in\n",
      "NumPy 2.2.6 as it may crash. To support both 1.x and 2.x\n",
      "versions of NumPy, modules must be compiled with NumPy 2.0.\n",
      "Some module may need to rebuild instead e.g. with 'pybind11>=2.12'.\n",
      "\n",
      "If you are a user of the module, the easiest solution will be to\n",
      "downgrade to 'numpy<2' or try to upgrade the affected module.\n",
      "We expect that some modules will need time to support NumPy 2.\n",
      "\n",
      "Traceback (most recent call last):  File \"/opt/conda/lib/python3.10/runpy.py\", line 196, in _run_module_as_main\n",
      "    return _run_code(code, main_globals, None,\n",
      "  File \"/opt/conda/lib/python3.10/runpy.py\", line 86, in _run_code\n",
      "    exec(code, run_globals)\n",
      "  File \"/opt/conda/lib/python3.10/site-packages/ipykernel_launcher.py\", line 17, in <module>\n",
      "    app.launch_new_instance()\n",
      "  File \"/opt/conda/lib/python3.10/site-packages/traitlets/config/application.py\", line 1041, in launch_instance\n",
      "    app.start()\n",
      "  File \"/opt/conda/lib/python3.10/site-packages/ipykernel/kernelapp.py\", line 711, in start\n",
      "    self.io_loop.start()\n",
      "  File \"/opt/conda/lib/python3.10/site-packages/tornado/platform/asyncio.py\", line 215, in start\n",
      "    self.asyncio_loop.run_forever()\n",
      "  File \"/opt/conda/lib/python3.10/asyncio/base_events.py\", line 603, in run_forever\n",
      "    self._run_once()\n",
      "  File \"/opt/conda/lib/python3.10/asyncio/base_events.py\", line 1899, in _run_once\n",
      "    handle._run()\n",
      "  File \"/opt/conda/lib/python3.10/asyncio/events.py\", line 80, in _run\n",
      "    self._context.run(self._callback, *self._args)\n",
      "  File \"/opt/conda/lib/python3.10/site-packages/ipykernel/kernelbase.py\", line 510, in dispatch_queue\n",
      "    await self.process_one()\n",
      "  File \"/opt/conda/lib/python3.10/site-packages/ipykernel/kernelbase.py\", line 499, in process_one\n",
      "    await dispatch(*args)\n",
      "  File \"/opt/conda/lib/python3.10/site-packages/ipykernel/kernelbase.py\", line 406, in dispatch_shell\n",
      "    await result\n",
      "  File \"/opt/conda/lib/python3.10/site-packages/ipykernel/kernelbase.py\", line 729, in execute_request\n",
      "    reply_content = await reply_content\n",
      "  File \"/opt/conda/lib/python3.10/site-packages/ipykernel/ipkernel.py\", line 411, in do_execute\n",
      "    res = shell.run_cell(\n",
      "  File \"/opt/conda/lib/python3.10/site-packages/ipykernel/zmqshell.py\", line 530, in run_cell\n",
      "    return super().run_cell(*args, **kwargs)\n",
      "  File \"/opt/conda/lib/python3.10/site-packages/IPython/core/interactiveshell.py\", line 2945, in run_cell\n",
      "    result = self._run_cell(\n",
      "  File \"/opt/conda/lib/python3.10/site-packages/IPython/core/interactiveshell.py\", line 3000, in _run_cell\n",
      "    return runner(coro)\n",
      "  File \"/opt/conda/lib/python3.10/site-packages/IPython/core/async_helpers.py\", line 129, in _pseudo_sync_runner\n",
      "    coro.send(None)\n",
      "  File \"/opt/conda/lib/python3.10/site-packages/IPython/core/interactiveshell.py\", line 3203, in run_cell_async\n",
      "    has_raised = await self.run_ast_nodes(code_ast.body, cell_name,\n",
      "  File \"/opt/conda/lib/python3.10/site-packages/IPython/core/interactiveshell.py\", line 3382, in run_ast_nodes\n",
      "    if await self.run_code(code, result, async_=asy):\n",
      "  File \"/opt/conda/lib/python3.10/site-packages/IPython/core/interactiveshell.py\", line 3442, in run_code\n",
      "    exec(code_obj, self.user_global_ns, self.user_ns)\n",
      "  File \"/tmp/ipykernel_14610/3049354109.py\", line 7, in <module>\n",
      "    from spark_session import spark\n",
      "  File \"/home/user/work/spark_session.py\", line 8, in <module>\n",
      "    import pandas as pd\n",
      "  File \"/opt/conda/lib/python3.10/site-packages/pandas/__init__.py\", line 49, in <module>\n",
      "    from pandas.core.api import (\n",
      "  File \"/opt/conda/lib/python3.10/site-packages/pandas/core/api.py\", line 28, in <module>\n",
      "    from pandas.core.arrays import Categorical\n",
      "  File \"/opt/conda/lib/python3.10/site-packages/pandas/core/arrays/__init__.py\", line 1, in <module>\n",
      "    from pandas.core.arrays.arrow import ArrowExtensionArray\n",
      "  File \"/opt/conda/lib/python3.10/site-packages/pandas/core/arrays/arrow/__init__.py\", line 5, in <module>\n",
      "    from pandas.core.arrays.arrow.array import ArrowExtensionArray\n",
      "  File \"/opt/conda/lib/python3.10/site-packages/pandas/core/arrays/arrow/array.py\", line 66, in <module>\n",
      "    from pandas.core.arrays.masked import BaseMaskedArray\n",
      "  File \"/opt/conda/lib/python3.10/site-packages/pandas/core/arrays/masked.py\", line 61, in <module>\n",
      "    from pandas.core import (\n",
      "  File \"/opt/conda/lib/python3.10/site-packages/pandas/core/nanops.py\", line 52, in <module>\n",
      "    bn = import_optional_dependency(\"bottleneck\", errors=\"warn\")\n",
      "  File \"/opt/conda/lib/python3.10/site-packages/pandas/compat/_optional.py\", line 135, in import_optional_dependency\n",
      "    module = importlib.import_module(name)\n",
      "  File \"/opt/conda/lib/python3.10/importlib/__init__.py\", line 126, in import_module\n",
      "    return _bootstrap._gcd_import(name[level:], package, level)\n",
      "  File \"/opt/conda/lib/python3.10/site-packages/bottleneck/__init__.py\", line 7, in <module>\n",
      "    from .move import (move_argmax, move_argmin, move_max, move_mean, move_median,\n"
     ]
    },
    {
     "ename": "AttributeError",
     "evalue": "_ARRAY_API not found",
     "output_type": "error",
     "traceback": [
      "\u001b[0;31m---------------------------------------------------------------------------\u001b[0m",
      "\u001b[0;31mAttributeError\u001b[0m                            Traceback (most recent call last)",
      "\u001b[0;31mAttributeError\u001b[0m: _ARRAY_API not found"
     ]
    }
   ],
   "source": [
    "# Adiciona a pasta raiz do projeto ao sys.path\n",
    "import sys\n",
    "import os\n",
    "sys.path.append(os.path.abspath(os.path.join(\"..\")))\n",
    "\n",
    "## Importar a sessão spark criada no spark_session.py\n",
    "from spark_session import spark\n",
    "from minio import Minio\n",
    "from datetime import datetime\n"
   ]
  },
  {
   "cell_type": "code",
   "execution_count": 2,
   "id": "d4717380-171f-4099-a4ae-c714df154181",
   "metadata": {},
   "outputs": [],
   "source": [
    "path = f\"s3a://silver/geo_spatial_infos/{datetime.now().month}_{datetime.now().year}\"\n",
    "df = spark.read.format('parquet').load(path)\n",
    "df_geospatial = df.select('latitude','longitude').distinct().toPandas()"
   ]
  },
  {
   "cell_type": "code",
   "execution_count": 3,
   "id": "bf8e000d-71ee-4028-ae7e-ba4e8ff23455",
   "metadata": {},
   "outputs": [
    {
     "name": "stdout",
     "output_type": "stream",
     "text": [
      "Collecting numpy==1.26.4\n",
      "  Using cached numpy-1.26.4-cp310-cp310-manylinux_2_17_x86_64.manylinux2014_x86_64.whl (18.2 MB)\n",
      "Installing collected packages: numpy\n",
      "  Attempting uninstall: numpy\n",
      "    Found existing installation: numpy 2.2.6\n",
      "    Uninstalling numpy-2.2.6:\n",
      "      Successfully uninstalled numpy-2.2.6\n",
      "\u001b[31mERROR: pip's dependency resolver does not currently take into account all the packages that are installed. This behaviour is the source of the following dependency conflicts.\n",
      "scipy 1.9.3 requires numpy<1.26.0,>=1.18.5, but you have numpy 1.26.4 which is incompatible.\n",
      "numba 0.56.4 requires numpy<1.24,>=1.18, but you have numpy 1.26.4 which is incompatible.\u001b[0m\u001b[31m\n",
      "\u001b[0mSuccessfully installed numpy-1.26.4\n",
      "Note: you may need to restart the kernel to use updated packages.\n"
     ]
    }
   ],
   "source": [
    "pip install numpy==1.26.4"
   ]
  },
  {
   "cell_type": "code",
   "execution_count": 4,
   "id": "93b2b5d0-f758-4540-9b4b-eeaf74c4b2c9",
   "metadata": {},
   "outputs": [
    {
     "name": "stdout",
     "output_type": "stream",
     "text": [
      "Requirement already satisfied: geopandas in /opt/conda/lib/python3.10/site-packages (1.1.1)\n",
      "Requirement already satisfied: packaging in /opt/conda/lib/python3.10/site-packages (from geopandas) (22.0)\n",
      "Requirement already satisfied: pandas>=2.0.0 in /opt/conda/lib/python3.10/site-packages (from geopandas) (2.3.2)\n",
      "Requirement already satisfied: shapely>=2.0.0 in /opt/conda/lib/python3.10/site-packages (from geopandas) (2.1.1)\n",
      "Requirement already satisfied: pyogrio>=0.7.2 in /opt/conda/lib/python3.10/site-packages (from geopandas) (0.11.1)\n",
      "Requirement already satisfied: pyproj>=3.5.0 in /opt/conda/lib/python3.10/site-packages (from geopandas) (3.7.1)\n",
      "Requirement already satisfied: numpy>=1.24 in /opt/conda/lib/python3.10/site-packages (from geopandas) (1.26.4)\n",
      "Requirement already satisfied: pytz>=2020.1 in /opt/conda/lib/python3.10/site-packages (from pandas>=2.0.0->geopandas) (2022.7)\n",
      "Requirement already satisfied: python-dateutil>=2.8.2 in /opt/conda/lib/python3.10/site-packages (from pandas>=2.0.0->geopandas) (2.8.2)\n",
      "Requirement already satisfied: tzdata>=2022.7 in /opt/conda/lib/python3.10/site-packages (from pandas>=2.0.0->geopandas) (2025.2)\n",
      "Requirement already satisfied: certifi in /opt/conda/lib/python3.10/site-packages (from pyogrio>=0.7.2->geopandas) (2022.12.7)\n",
      "Requirement already satisfied: six>=1.5 in /opt/conda/lib/python3.10/site-packages (from python-dateutil>=2.8.2->pandas>=2.0.0->geopandas) (1.16.0)\n"
     ]
    }
   ],
   "source": [
    "!pip install geopandas"
   ]
  },
  {
   "cell_type": "code",
   "execution_count": 10,
   "id": "66e24bc0-0b6a-463d-80a4-9f7226c9d007",
   "metadata": {},
   "outputs": [],
   "source": [
    "import tempfile\n",
    "import requests\n",
    "import zipfile\n",
    "import geopandas as gpd\n",
    "from shapely.geometry import Point\n",
    "import json\n",
    "from pyspark.sql import functions as f"
   ]
  },
  {
   "cell_type": "code",
   "execution_count": 6,
   "id": "a4cce981-930c-4b75-8a37-db4c64c2b293",
   "metadata": {},
   "outputs": [
    {
     "name": "stdout",
     "output_type": "stream",
     "text": [
      "✅ Arquivo baixado do MinIO para: /tmp/tmpifgy4zds/arquivo.zip\n",
      "📂 Arquivos extraídos em: /tmp/tmpifgy4zds\n",
      "📍 Shapefile localizado: /tmp/tmpifgy4zds/tl_2023_us_county.shp\n"
     ]
    },
    {
     "name": "stderr",
     "output_type": "stream",
     "text": [
      "\n",
      "A module that was compiled using NumPy 1.x cannot be run in\n",
      "NumPy 2.2.6 as it may crash. To support both 1.x and 2.x\n",
      "versions of NumPy, modules must be compiled with NumPy 2.0.\n",
      "Some module may need to rebuild instead e.g. with 'pybind11>=2.12'.\n",
      "\n",
      "If you are a user of the module, the easiest solution will be to\n",
      "downgrade to 'numpy<2' or try to upgrade the affected module.\n",
      "We expect that some modules will need time to support NumPy 2.\n",
      "\n",
      "Traceback (most recent call last):  File \"/opt/conda/lib/python3.10/runpy.py\", line 196, in _run_module_as_main\n",
      "    return _run_code(code, main_globals, None,\n",
      "  File \"/opt/conda/lib/python3.10/runpy.py\", line 86, in _run_code\n",
      "    exec(code, run_globals)\n",
      "  File \"/opt/conda/lib/python3.10/site-packages/ipykernel_launcher.py\", line 17, in <module>\n",
      "    app.launch_new_instance()\n",
      "  File \"/opt/conda/lib/python3.10/site-packages/traitlets/config/application.py\", line 1041, in launch_instance\n",
      "    app.start()\n",
      "  File \"/opt/conda/lib/python3.10/site-packages/ipykernel/kernelapp.py\", line 711, in start\n",
      "    self.io_loop.start()\n",
      "  File \"/opt/conda/lib/python3.10/site-packages/tornado/platform/asyncio.py\", line 215, in start\n",
      "    self.asyncio_loop.run_forever()\n",
      "  File \"/opt/conda/lib/python3.10/asyncio/base_events.py\", line 603, in run_forever\n",
      "    self._run_once()\n",
      "  File \"/opt/conda/lib/python3.10/asyncio/base_events.py\", line 1899, in _run_once\n",
      "    handle._run()\n",
      "  File \"/opt/conda/lib/python3.10/asyncio/events.py\", line 80, in _run\n",
      "    self._context.run(self._callback, *self._args)\n",
      "  File \"/opt/conda/lib/python3.10/site-packages/ipykernel/kernelbase.py\", line 510, in dispatch_queue\n",
      "    await self.process_one()\n",
      "  File \"/opt/conda/lib/python3.10/site-packages/ipykernel/kernelbase.py\", line 499, in process_one\n",
      "    await dispatch(*args)\n",
      "  File \"/opt/conda/lib/python3.10/site-packages/ipykernel/kernelbase.py\", line 406, in dispatch_shell\n",
      "    await result\n",
      "  File \"/opt/conda/lib/python3.10/site-packages/ipykernel/kernelbase.py\", line 729, in execute_request\n",
      "    reply_content = await reply_content\n",
      "  File \"/opt/conda/lib/python3.10/site-packages/ipykernel/ipkernel.py\", line 411, in do_execute\n",
      "    res = shell.run_cell(\n",
      "  File \"/opt/conda/lib/python3.10/site-packages/ipykernel/zmqshell.py\", line 530, in run_cell\n",
      "    return super().run_cell(*args, **kwargs)\n",
      "  File \"/opt/conda/lib/python3.10/site-packages/IPython/core/interactiveshell.py\", line 2945, in run_cell\n",
      "    result = self._run_cell(\n",
      "  File \"/opt/conda/lib/python3.10/site-packages/IPython/core/interactiveshell.py\", line 3000, in _run_cell\n",
      "    return runner(coro)\n",
      "  File \"/opt/conda/lib/python3.10/site-packages/IPython/core/async_helpers.py\", line 129, in _pseudo_sync_runner\n",
      "    coro.send(None)\n",
      "  File \"/opt/conda/lib/python3.10/site-packages/IPython/core/interactiveshell.py\", line 3203, in run_cell_async\n",
      "    has_raised = await self.run_ast_nodes(code_ast.body, cell_name,\n",
      "  File \"/opt/conda/lib/python3.10/site-packages/IPython/core/interactiveshell.py\", line 3382, in run_ast_nodes\n",
      "    if await self.run_code(code, result, async_=asy):\n",
      "  File \"/opt/conda/lib/python3.10/site-packages/IPython/core/interactiveshell.py\", line 3442, in run_code\n",
      "    exec(code_obj, self.user_global_ns, self.user_ns)\n",
      "  File \"/tmp/ipykernel_14610/519323742.py\", line 39, in <module>\n",
      "    gdf = gpd.read_file(shp_path)\n",
      "  File \"/opt/conda/lib/python3.10/site-packages/geopandas/io/file.py\", line 289, in _read_file\n",
      "    engine = _check_engine(engine, \"'read_file' function\")\n",
      "  File \"/opt/conda/lib/python3.10/site-packages/geopandas/io/file.py\", line 131, in _check_engine\n",
      "    _import_pyogrio()\n",
      "  File \"/opt/conda/lib/python3.10/site-packages/geopandas/io/file.py\", line 84, in _import_pyogrio\n",
      "    import pyogrio\n",
      "  File \"/opt/conda/lib/python3.10/site-packages/pyogrio/__init__.py\", line 30, in <module>\n",
      "    from pyogrio.geopandas import read_dataframe, write_dataframe\n",
      "  File \"/opt/conda/lib/python3.10/site-packages/pyogrio/geopandas.py\", line 8, in <module>\n",
      "    from pyogrio._compat import (\n",
      "  File \"/opt/conda/lib/python3.10/site-packages/pyogrio/_compat.py\", line 7, in <module>\n",
      "    import pyarrow\n",
      "  File \"/opt/conda/lib/python3.10/site-packages/pyarrow/__init__.py\", line 65, in <module>\n",
      "    import pyarrow.lib as _lib\n"
     ]
    },
    {
     "ename": "AttributeError",
     "evalue": "_ARRAY_API not found",
     "output_type": "error",
     "traceback": [
      "\u001b[0;31m---------------------------------------------------------------------------\u001b[0m",
      "\u001b[0;31mAttributeError\u001b[0m                            Traceback (most recent call last)",
      "\u001b[0;31mAttributeError\u001b[0m: _ARRAY_API not found"
     ]
    },
    {
     "name": "stdout",
     "output_type": "stream",
     "text": [
      "✅ GeoDataFrame carregado com sucesso!\n"
     ]
    }
   ],
   "source": [
    "\n",
    "# Configura o cliente MinIO (mesmo de antes)\n",
    "client = Minio(\n",
    "    \"minio:9000\",\n",
    "    access_key=\"minio\",\n",
    "    secret_key=\"minio123\",\n",
    "    secure=False\n",
    ")\n",
    "\n",
    "# Dados do arquivo no MinIO\n",
    "bucket = \"raw\"\n",
    "minio_path = \"geospatial/tl_2023_us_county.zip\"\n",
    "\n",
    "# Cria diretório temporário\n",
    "with tempfile.TemporaryDirectory() as tmp_dir:\n",
    "    zip_path = os.path.join(tmp_dir, \"arquivo.zip\")\n",
    "\n",
    "    # 📥 Baixa o ZIP do MinIO\n",
    "    client.fget_object(\n",
    "        bucket,\n",
    "        minio_path,\n",
    "        zip_path\n",
    "    )\n",
    "    print(f\"✅ Arquivo baixado do MinIO para: {zip_path}\")\n",
    "\n",
    "    # 📦 Extrai o conteúdo do ZIP\n",
    "    with zipfile.ZipFile(zip_path, 'r') as zip_ref:\n",
    "        zip_ref.extractall(tmp_dir)\n",
    "        print(f\"📂 Arquivos extraídos em: {tmp_dir}\")\n",
    "\n",
    "    # 🔍 Localiza o .shp extraído\n",
    "    shp_file = [f for f in os.listdir(tmp_dir) if f.endswith(\".shp\")]\n",
    "    if not shp_file:\n",
    "        raise FileNotFoundError(\"Nenhum arquivo .shp encontrado no ZIP extraído.\")\n",
    "    \n",
    "    shp_path = os.path.join(tmp_dir, shp_file[0])\n",
    "    print(f\"📍 Shapefile localizado: {shp_path}\")\n",
    "\n",
    "    # 📚 Lê o shapefile com geopandas\n",
    "    gdf = gpd.read_file(shp_path)\n",
    "    print(\"✅ GeoDataFrame carregado com sucesso!\")\n",
    "\n"
   ]
  },
  {
   "cell_type": "code",
   "execution_count": 12,
   "id": "768b1ad3-b707-462e-bde2-72b791f56733",
   "metadata": {},
   "outputs": [],
   "source": [
    "# Cria uma coluna de geometria a partir das coordenadas\n",
    "geometry = [Point(xy) for xy in zip(df_geospatial['longitude'], df_geospatial['latitude'])]\n",
    "\n",
    "# Cria o GeoDataFrame com CRS WGS84 (EPSG:4326), que é o padrão GPS\n",
    "gdf_points = gpd.GeoDataFrame(df_geospatial.copy(), geometry=geometry, crs=\"EPSG:4326\")\n",
    "\n",
    "# Transforma para o mesmo CRS do GeoDataFrame do shapefile (gdf)\n",
    "gdf_points = gdf_points.to_crs(gdf.crs)\n",
    "\n",
    "# Faz o spatial join para agregar dados do shapefile aos pontos\n",
    "gdf_joined = gpd.sjoin(gdf_points, gdf, how=\"left\", predicate=\"within\")\n",
    "\n",
    "# Remove a coluna de geometria para voltar ao formato tabular\n",
    "df_enriched = gdf_joined.drop(columns='geometry')\n",
    "\n",
    "#  Seleciona as colunas que você quer no resultado final\n",
    "df_final = df_enriched[['latitude', 'longitude', 'COUNTYFP', 'NAME', 'NAMELSAD']]\n",
    "\n",
    "\n",
    "#  Converte o pandas DataFrame para JSON (orientação records - lista de dicts)\n",
    "json_records = df_final.to_json(orient='records')\n",
    "\n",
    "#  Transforma a string JSON em lista de dicionários Python\n",
    "list_of_dicts = json.loads(json_records)\n",
    "\n",
    "#  Cria o Spark DataFrame a partir da lista de dicionários\n",
    "df_spark_enriched = spark.createDataFrame(list_of_dicts).select(\n",
    "    'latitude', 'longitude',\n",
    "    f.col('COUNTYFP').alias('county_code'),\n",
    "    f.col('NAME').alias('county_name'),\n",
    "    f.col('NAMELSAD').alias('county_full_name'),\n",
    ")\n",
    "\n"
   ]
  },
  {
   "cell_type": "code",
   "execution_count": 14,
   "id": "1f07d099-3009-41b3-8993-8b2e3f7ed845",
   "metadata": {},
   "outputs": [],
   "source": [
    "# Definição de como salvar os arquivos\n",
    "bucket = 'silver'\n",
    "project_name = 'geo_spatial_full'\n",
    "\n",
    "save_path = f\"s3a://{bucket}/{project_name}/{datetime.now().month}_{datetime.now().year}\"\n",
    "\n",
    "df_spark_enriched.write\\\n",
    "    .mode(\"overwrite\") \\\n",
    "    .format('delta')\\\n",
    "    .save(save_path)"
   ]
  },
  {
   "cell_type": "code",
   "execution_count": 15,
   "id": "c9d6aad8-d45a-4f2b-9c2e-a624bb94b6e0",
   "metadata": {},
   "outputs": [
    {
     "name": "stdout",
     "output_type": "stream",
     "text": [
      "Requirement already satisfied: numpy in /opt/conda/lib/python3.10/site-packages (1.26.4)\n",
      "Collecting numpy\n",
      "  Using cached numpy-2.2.6-cp310-cp310-manylinux_2_17_x86_64.manylinux2014_x86_64.whl (16.8 MB)\n",
      "Installing collected packages: numpy\n",
      "  Attempting uninstall: numpy\n",
      "    Found existing installation: numpy 1.26.4\n",
      "    Uninstalling numpy-1.26.4:\n",
      "      Successfully uninstalled numpy-1.26.4\n",
      "\u001b[31mERROR: pip's dependency resolver does not currently take into account all the packages that are installed. This behaviour is the source of the following dependency conflicts.\n",
      "scipy 1.9.3 requires numpy<1.26.0,>=1.18.5, but you have numpy 2.2.6 which is incompatible.\n",
      "numba 0.56.4 requires numpy<1.24,>=1.18, but you have numpy 2.2.6 which is incompatible.\u001b[0m\u001b[31m\n",
      "\u001b[0mSuccessfully installed numpy-2.2.6\n"
     ]
    },
    {
     "name": "stderr",
     "output_type": "stream",
     "text": [
      "----------------------------------------\n",
      "Exception occurred during processing of request from ('127.0.0.1', 34120)\n",
      "Traceback (most recent call last):\n",
      "  File \"/opt/conda/lib/python3.10/socketserver.py\", line 316, in _handle_request_noblock\n",
      "    self.process_request(request, client_address)\n",
      "  File \"/opt/conda/lib/python3.10/socketserver.py\", line 347, in process_request\n",
      "    self.finish_request(request, client_address)\n",
      "  File \"/opt/conda/lib/python3.10/socketserver.py\", line 360, in finish_request\n",
      "    self.RequestHandlerClass(request, client_address, self)\n",
      "  File \"/opt/conda/lib/python3.10/socketserver.py\", line 747, in __init__\n",
      "    self.handle()\n",
      "  File \"/usr/local/spark/python/pyspark/accumulators.py\", line 281, in handle\n",
      "    poll(accum_updates)\n",
      "  File \"/usr/local/spark/python/pyspark/accumulators.py\", line 253, in poll\n",
      "    if func():\n",
      "  File \"/usr/local/spark/python/pyspark/accumulators.py\", line 257, in accum_updates\n",
      "    num_updates = read_int(self.rfile)\n",
      "  File \"/usr/local/spark/python/pyspark/serializers.py\", line 595, in read_int\n",
      "    raise EOFError\n",
      "EOFError\n",
      "----------------------------------------\n"
     ]
    }
   ],
   "source": [
    "!pip install --upgrade numpy"
   ]
  }
 ],
 "metadata": {
  "kernelspec": {
   "display_name": "Python 3 (ipykernel)",
   "language": "python",
   "name": "python3"
  },
  "language_info": {
   "codemirror_mode": {
    "name": "ipython",
    "version": 3
   },
   "file_extension": ".py",
   "mimetype": "text/x-python",
   "name": "python",
   "nbconvert_exporter": "python",
   "pygments_lexer": "ipython3",
   "version": "3.10.8"
  }
 },
 "nbformat": 4,
 "nbformat_minor": 5
}
